<?xml version="1.0" ?>
<robot name="Telemarketing" xmlns:xacro="http://www.ros.org/wiki/xacro">
  
  <xacro:include filename="$(find telemarketing_description)/urdf/links_joints.xacro" />
  <xacro:include filename="$(find telemarketing_description)/urdf/gazebo.xacro" />
  
  <material name="white">
    <color rgba="1 1 1 1"/>
  </material>

  <material name="black">
    <color rgba="0 0 0 1"/>
  </material>

  <material name="blue">
    <color rgba="0 0 1 1"/>
  </material>

  <material name="grey">
    <color rgba="0.750 0.750 0.750 1"/>
  </material>

  <material name="orange">
    <color rgba="0.949 0.361 0.098 1"/>
  </material>

  <!-- Robot description -->
  <m_link_mesh name="base_link"
              origin_rpy="0 1.5708 3.1416" origin_xyz="0 0.158 0.5"
              mass="1"
              ixx="1177287.158" ixy="-246402.075" ixz="-453961.379"
              iyy="13057357.025" iyz="-55693.992"
              izz="13181014.451"
              material="grey"
              meshfile="package://telemarketing_description/meshes/main_frame.stl"
              meshscale="0.010335 0.010335 0.010335" />

  <joint name="r_dwheel_joint" type="continuous">
      <parent link="base_link"/>
      <child link="r_dwheel"/>
      <origin xyz="-0.026 -0.174 0.661" rpy="1.5708 0.0 0"/>
      <axis xyz="0 0 -1"/>
  </joint>

  <m_link_mesh name="r_dwheel"
              origin_rpy="0 0 0" origin_xyz="0 0 0"
              mass="10"
              ixx="0.1798" ixy="0" ixz="0"
              iyy="0.1081" iyz="0"
              izz="0.1798"
              material="black"
              meshfile="package://telemarketing_description/meshes/main_wheel.stl"
              meshscale="0.010335 0.010335 0.010335" />

  <joint name="l_dwheel_joint" type="continuous">
      <parent link="base_link"/>
      <child link="l_dwheel"/>
      <origin xyz="-0.007 0.169 0.661" rpy="1.5708 0.0 0"/>
      <axis xyz="0 0 -1"/>
  </joint>

  <m_link_mesh name="l_dwheel"
              origin_rpy="0 0 0" origin_xyz="0 0 0"
              mass="10"
              ixx="0.1798" ixy="0" ixz="0"
              iyy="0.1081" iyz="0"
              izz="0.1798"
              material="black"
              meshfile="package://telemarketing_description/meshes/main_wheel.stl"
              meshscale="0.010335 0.010335 0.010335" />

  <joint name="fr_cwheel_joint" type="continuous">
      <parent link="base_link"/>
      <child link="fr_cwheel"/>
      <origin xyz="0.165 -0.186 0.609" rpy="1.5708 0.0 0"/>
      <axis xyz="0 1 0"/>
  </joint>

  <m_link_mesh name="fr_cwheel"
              origin_rpy="0 0 0" origin_xyz="0 0 0"
              mass="10"
              ixx="0.1798" ixy="0" ixz="0"
              iyy="0.1081" iyz="0"
              izz="0.1798"
              material="black"
              meshfile="package://telemarketing_description/meshes/caster_wheel.stl"
              meshscale="0.010335 0.010335 0.010335" />

  <joint name="fl_cwheel_joint" type="continuous">
      <parent link="base_link"/>
      <child link="fl_cwheel"/>
      <origin xyz="0.165 0.181 0.609" rpy="1.5708 0.0 0"/>
      <axis xyz="0 1 0"/>
  </joint>

  <m_link_mesh name="fl_cwheel"
              origin_rpy="0 0 0" origin_xyz="0 0 0"
              mass="10"
              ixx="0.1798" ixy="0" ixz="0"
              iyy="0.1081" iyz="0"
              izz="0.1798"
              material="black"
              meshfile="package://telemarketing_description/meshes/caster_wheel.stl"
              meshscale="0.010335 0.010335 0.010335" />

  <joint name="br_cwheel_joint" type="continuous">
      <parent link="base_link"/>
      <child link="br_cwheel"/>
      <origin xyz="-0.199 -0.186 0.609" rpy="1.5708 0.0 0"/>
      <axis xyz="0 1 0"/>
  </joint>

  <m_link_mesh name="br_cwheel"
              origin_rpy="0 0 0" origin_xyz="0 0 0"
              mass="10"
              ixx="0.1798" ixy="0" ixz="0"
              iyy="0.1081" iyz="0"
              izz="0.1798"
              material="black"
              meshfile="package://telemarketing_description/meshes/caster_wheel.stl"
              meshscale="0.010335 0.010335 0.010335" />

  <joint name="bl_cwheel_joint" type="continuous">
      <parent link="base_link"/>
      <child link="bl_cwheel"/>
      <origin xyz="-0.199 0.181 0.609" rpy="1.5708 0.0 0"/>
      <axis xyz="0 1 0"/>
  </joint>

  <m_link_mesh name="bl_cwheel"
              origin_rpy="0 0 0" origin_xyz="0 0 0"
              mass="10"
              ixx="0.1798" ixy="0" ixz="0"
              iyy="0.1081" iyz="0"
              izz="0.1798"
              material="black"
              meshfile="package://telemarketing_description/meshes/caster_wheel.stl"
              meshscale="0.010335 0.010335 0.010335" />

  <joint name="lidar_joint" type="fixed">
    <axis xyz="0 1 0" />
    <origin xyz="0.1650 0 0.920" rpy="0 0 0"/>
    <parent link="base_link"/>
    <child link="lidar_link"/>
  </joint>

  <link name="lidar_link">
    <collision>
      <origin xyz="0 0 0" rpy="1.5708 0 1.5708"/>
      <geometry>
        <mesh filename="package://telemarketing_description/meshes/lidar.stl" scale="0.010335 0.010335 0.010335"/>
      </geometry>
    </collision>
    <visual>
      <origin xyz="0 0 0" rpy="1.5708 0 1.5708"/>
      <geometry>
        <mesh filename="package://telemarketing_description/meshes/lidar.stl" scale="0.010335 0.010335 0.010335"/>
      </geometry>
      <material name="blue"/>
    </visual>
    <inertial>
      <mass value="0.370" />
      <origin xyz="0 0 0" rpy="1.5708 0 1.5708"/>
      <inertia ixx="1e-6" ixy="0" ixz="0" iyy="1e-6" iyz="0" izz="1e-6" />
    </inertial>
  </link>

  <joint name="depth_joint" type="fixed">
    <axis xyz="0 1 0" />
    <origin xyz="0.165 0 1.417" rpy="0 0 0"/>
    <parent link="base_link"/>
    <child link="depth_link"/>
  </joint>

  <link name="depth_link">
    <collision>
      <origin xyz="0 0 0" rpy="1.3090 0 1.5708"/>
      <geometry>
        <mesh filename="package://telemarketing_description/meshes/depth_camera.stl" scale="0.010335 0.010335 0.010335"/>
      </geometry>
    </collision>
    <visual>
      <origin xyz="0 0 0" rpy="1.3090 0 1.5708"/>
      <geometry>
        <mesh filename="package://telemarketing_description/meshes/depth_camera.stl" scale="0.010335 0.010335 0.010335"/>
      </geometry>
      <material name="grey"/>
    </visual>
    <inertial>
      <mass value="1e-5" />
      <origin xyz="0 0 0" rpy="0 0 0"/>
      <inertia ixx="1e-6" ixy="0" ixz="0" iyy="1e-6" iyz="0" izz="1e-6" />
    </inertial>
  </link>

  <joint name="depth_optical_joint" type="fixed">
    <origin xyz="0 0 0" rpy="-1.5708 0 -1.5708"/>
    <parent link="depth_link"/>
    <child link="depth_optical_link"/>
  </joint>

  <link name="depth_optical_link"/>

             

</robot>
