<?xml version="1.0" ?>
<robot name="Telemarketing" xmlns:xacro="http://www.ros.org/wiki/xacro">
  
  <xacro:include filename="$(find telemarketing_description)/urdf/links_joints.xacro" />
  <xacro:include filename="$(find telemarketing_description)/urdf/gazebo.xacro" />
  
  <material name="white">
    <color rgba="1 1 1 1"/>
  </material>

  <material name="black">
    <color rgba="0 0 0 1"/>
  </material>

  <material name="blue">
    <color rgba="0 0 1 1"/>
  </material>

  <material name="grey">
    <color rgba="0.332 0.332 0.332 1"/>
  </material>

  <material name="orange">
    <color rgba="0.949 0.361 0.098 1"/>
  </material>

  <!-- Robot description 0.311 0.3455 0.1016 -->
  <m_link_mesh name="base_link"
              origin_rpy="0 1.5708 3.1416" origin_xyz="0 0.158 0.5"
              mass="1"
              ixx="1177287.158" ixy="-246402.075" ixz="-453961.379"
              iyy="13057357.025" iyz="-55693.992"
              izz="13181014.451"
              material="white"
              meshfile="package://telemarketing_description/meshes/main_frame.stl"
              meshscale="0.010335 0.010335 0.010335" />

  <joint name="l_dwheel_joint" type="continuous">
      <parent link="base_link"/>
      <child link="l_dwheel"/>
      <origin xyz="-0.065 -0.144 0.661" rpy="0.0 0.0 0"/>
      <axis xyz="0 1 0"/>
  </joint>

  <m_link_mesh name="l_dwheel"
              origin_rpy="0 0 0" origin_xyz="0 0 0"
              mass="10"
              ixx="0.1798" ixy="0" ixz="0"
              iyy="0.1081" iyz="0"
              izz="0.1798"
              material="black"
              meshfile="package://telemarketing_description/meshes/main_wheel.stl"
              meshscale="0.010335 0.010335 0.010335" />



</robot>
